Workbook
Name deflator_2012_2009: 'raw data'!$U$5
Name deflator_2017_2009: 'raw data'!$U$6
Name deflator_2017_2012: 'raw data'!$U$7

Sheet data 2017 USD
A1: date | B1: GDP 2014 est | C1: potential GDP 2014 est | D1: GDP 2015 est | E1: potential GDP 2015 est | F1: GDP 2016 est | G1: potential GDP 2016 est | H1: GDP 2022 est | I1: potential GDP 2022 est | J1: GDP 2024 est | K1: potential GDP 2024 est | L1: GDP 2025 est | M1: potential GDP 2025 est | P1: deflator from 2009 dollars | Q1: deflator from 2012 dollars | R1: deflator from 2017 dollars
A2: 36526 | B2: ='raw data'!C5*$P$2 -> 13955.674 | C2: ='raw data'!D5*$P$2 -> 13620.194 | D2: ='raw data'!E5*$P$2 -> 13955.674 | E2: ='raw data'!F5*$P$2 -> 13689.865 | F2: ='raw data'!G5*$P$2 -> 13955.674 | G2: ='raw data'!H5*$P$2 -> 13704.318 | H2: ='raw data'!I5*$Q$2 -> 13880.789 | I2: ='raw data'!J5*$Q$2 -> 13688.647 | J2: ='raw data'!K5*$R$2 -> 13878.147 | K2: ='raw data'!L5*$R$2 -> 13657.91 | L2: ='raw data'!M5*$R$2 -> 13878.147 | M2: ='raw data'!N5*$R$2 -> 13649.992 | P2: =deflator_2017_2009 -> 1.1291821 | Q2: =deflator_2017_2012 -> 1.0730977 | R2: 1
A3: 36617 | B3: ='raw data'!C6*$P$2 -> 14219.225 | C3: ='raw data'!D6*$P$2 -> 13743.501 | D3: ='raw data'!E6*$P$2 -> 14219.225 | E3: ='raw data'!F6*$P$2 -> 13812.494 | F3: ='raw data'!G6*$P$2 -> 14219.225 | G3: ='raw data'!H6*$P$2 -> 13825.479 | H3: ='raw data'!I6*$Q$2 -> 14133.501 | I3: ='raw data'!J6*$Q$2 -> 13827.454 | J3: ='raw data'!K6*$R$2 -> 14130.908 | K3: ='raw data'!L6*$R$2 -> 13802.558 | L3: ='raw data'!M6*$R$2 -> 14130.908 | M3: ='raw data'!N6*$R$2 -> 13792.736
A4: 36708 | B4: ='raw data'!C7*$P$2 -> 14236.389 | C4: ='raw data'!D7*$P$2 -> 13868.388 | D4: ='raw data'!E7*$P$2 -> 14236.389 | E4: ='raw data'!F7*$P$2 -> 13937.494 | F4: ='raw data'!G7*$P$2 -> 14236.389 | G4: ='raw data'!H7*$P$2 -> 13948.56 | H4: ='raw data'!I7*$Q$2 -> 14147.602 | I4: ='raw data'!J7*$Q$2 -> 13961.052 | J4: ='raw data'!K7*$R$2 -> 14145.312 | K4: ='raw data'!L7*$R$2 -> 13940.66 | L4: ='raw data'!M7*$R$2 -> 14145.312 | M4: ='raw data'!N7*$R$2 -> 13929.502
A5: 36800 | B5: ='raw data'!C8*$P$2 -> 14317.238 | C5: ='raw data'!D8*$P$2 -> 13994.405 | D5: ='raw data'!E8*$P$2 -> 14317.238 | E5: ='raw data'!F8*$P$2 -> 14064.414 | F5: ='raw data'!G8*$P$2 -> 14317.238 | G5: ='raw data'!H8*$P$2 -> 14073.222 | H5: ='raw data'!I8*$Q$2 -> 14231.69 | I5: ='raw data'!J8*$Q$2 -> 14088.855 | J5: ='raw data'!K8*$R$2 -> 14229.765 | K5: ='raw data'!L8*$R$2 -> 14071.402 | L5: ='raw data'!M8*$R$2 -> 14229.765 | M5: ='raw data'!N8*$R$2 -> 14059.357
A6: 36892 | B6: ='raw data'!C9*$P$2 -> 14276.588 | C6: ='raw data'!D9*$P$2 -> 14121.438 | D6: ='raw data'!E9*$P$2 -> 14276.588 | E6: ='raw data'!F9*$P$2 -> 14194.157 | F6: ='raw data'!G9*$P$2 -> 14276.588 | G6: ='raw data'!H9*$P$2 -> 14200.819 | H6: ='raw data'!I9*$Q$2 -> 14185.548 | I6: ='raw data'!J9*$Q$2 -> 14210.632 | J6: ='raw data'!K9*$R$2 -> 14183.12 | K6: ='raw data'!L9*$R$2 -> 14194.982 | L6: ='raw data'!M9*$R$2 -> 14183.12 | M6: ='raw data'!N9*$R$2 -> 14182.387
A7: 36982 | B7: ='raw data'!C10*$P$2 -> 14352.243 | C7: ='raw data'!D10*$P$2 -> 14248.358 | D7: ='raw data'!E10*$P$2 -> 14352.243 | E7: ='raw data'!F10*$P$2 -> 14323.336 | F7: ='raw data'!G10*$P$2 -> 14352.243 | G7: ='raw data'!H10*$P$2 -> 14328.191 | H7: ='raw data'!I10*$Q$2 -> 14273.695 | I7: ='raw data'!J10*$Q$2 -> 14326.283 | J7: ='raw data'!K10*$R$2 -> 14271.694 | K7: ='raw data'!L10*$R$2 -> 14311.54 | L7: ='raw data'!M10*$R$2 -> 14271.694 | M7: ='raw data'!N10*$R$2 -> 14298.498
A8: 37073 | B8: ='raw data'!C11*$P$2 -> 14306.85 | C8: ='raw data'!D11*$P$2 -> 14374.939 | D8: ='raw data'!E11*$P$2 -> 14306.85 | E8: ='raw data'!F11*$P$2 -> 14451.611 | F8: ='raw data'!G11*$P$2 -> 14306.85 | G8: ='raw data'!H11*$P$2 -> 14454.773 | H8: ='raw data'!I11*$Q$2 -> 14216.551 | I8: ='raw data'!J11*$Q$2 -> 14435.852 | J8: ='raw data'!K11*$R$2 -> 14214.516 | K8: ='raw data'!L11*$R$2 -> 14421.269 | L8: ='raw data'!M11*$R$2 -> 14214.516 | M8: ='raw data'!N11*$R$2 -> 14407.705
A9: 37165 | B9: ='raw data'!C12*$P$2 -> 14346.597 | C9: ='raw data'!D12*$P$2 -> 14500.617 | D9: ='raw data'!E12*$P$2 -> 14346.597 | E9: ='raw data'!F12*$P$2 -> 14577.966 | F9: ='raw data'!G12*$P$2 -> 14346.597 | G9: ='raw data'!H12*$P$2 -> 14579.434 | H9: ='raw data'!I12*$Q$2 -> 14255.975 | I9: ='raw data'!J12*$Q$2 -> 14540.021 | J9: ='raw data'!K12*$R$2 -> 14253.574 | K9: ='raw data'!L12*$R$2 -> 14525.226 | L9: ='raw data'!M12*$R$2 -> 14253.574 | M9: ='raw data'!N12*$R$2 -> 14510.935
A10: 37257 | B10: ='raw data'!C13*$P$2 -> 14478.711 | C10: ='raw data'!D13*$P$2 -> 14623.472 | D10: ='raw data'!E13*$P$2 -> 14478.711 | E10: ='raw data'!F13*$P$2 -> 14698.337 | F10: ='raw data'!G13*$P$2 -> 14478.711 | G10: ='raw data'!H13*$P$2 -> 14698.45 | H10: ='raw data'!I13*$Q$2 -> 14374.047 | I10: ='raw data'!J13*$Q$2 -> 14639.227 | J10: ='raw data'!K13*$R$2 -> 14372.785 | K10: ='raw data'!L13*$R$2 -> 14624.003 | L10: ='raw data'!M13*$R$2 -> 14372.785 | M10: ='raw data'!N13*$R$2 -> 14608.737
A11: 37347 | B11: ='raw data'!C14*$P$2 -> 14558.544 | C11: ='raw data'!D14*$P$2 -> 14746.779 | D11: ='raw data'!E14*$P$2 -> 14558.544 | E11: ='raw data'!F14*$P$2 -> 14817.014 | F11: ='raw data'!G14*$P$2 -> 14558.544 | G11: ='raw data'!H14*$P$2 -> 14815.659 | H11: ='raw data'!I14*$Q$2 -> 14462.52 | I11: ='raw data'!J14*$Q$2 -> 14735.271 | J11: ='raw data'!K14*$R$2 -> 14460.848 | K11: ='raw data'!L14*$R$2 -> 14719.439 | L11: ='raw data'!M14*$R$2 -> 14460.848 | M11: ='raw data'!N14*$R$2 -> 14702.897
A12: 37438 | B12: ='raw data'!C15*$P$2 -> 14629.457 | C12: ='raw data'!D15*$P$2 -> 14868.166 | D12: ='raw data'!E15*$P$2 -> 14629.457 | E12: ='raw data'!F15*$P$2 -> 14932.755 | F12: ='raw data'!G15*$P$2 -> 14629.457 | G12: ='raw data'!H15*$P$2 -> 14929.819 | H12: ='raw data'!I15*$Q$2 -> 14520.88 | I12: ='raw data'!J15*$Q$2 -> 14829.59 | J12: ='raw data'!K15*$R$2 -> 14519.633 | K12: ='raw data'!L15*$R$2 -> 14813.102 | L12: ='raw data'!M15*$R$2 -> 14519.633 | M12: ='raw data'!N15*$R$2 -> 14795.138
A13: 37530 | B13: ='raw data'!C16*$P$2 -> 14638.716 | C13: ='raw data'!D16*$P$2 -> 14987.295 | D13: ='raw data'!E16*$P$2 -> 14638.716 | E13: ='raw data'!F16*$P$2 -> 15045.673 | F13: ='raw data'!G16*$P$2 -> 14638.716 | G13: ='raw data'!H16*$P$2 -> 15040.931 | H13: ='raw data'!I16*$Q$2 -> 14539.853 | I13: ='raw data'!J16*$Q$2 -> 14922.575 | J13: ='raw data'!K16*$R$2 -> 14537.58 | K13: ='raw data'!L16*$R$2 -> 14905.536 | L13: ='raw data'!M16*$R$2 -> 14537.58 | M13: ='raw data'!N16*$R$2 -> 14886.176
A14: 37622 | B14: ='raw data'!C17*$P$2 -> 14714.597 | C14: ='raw data'!D17*$P$2 -> 15103.601 | D14: ='raw data'!E17*$P$2 -> 14714.597 | E14: ='raw data'!F17*$P$2 -> 15155.995 | F14: ='raw data'!G17*$P$2 -> 14714.597 | G14: ='raw data'!H17*$P$2 -> 15148.994 | H14: ='raw data'!I17*$Q$2 -> 14614.983 | I14: ='raw data'!J17*$Q$2 -> 15015.303 | J14: ='raw data'!K17*$R$2 -> 14614.141 | K14: ='raw data'!L17*$R$2 -> 14997.837 | L14: ='raw data'!M17*$R$2 -> 14614.141 | M14: ='raw data'!N17*$R$2 -> 14977.199
... A60: 41821 | B60: ='raw data'!C63*$P$2 -> 18236.968 | C60: ='raw data'!D63*$P$2 -> 18896.297 | D60: ='raw data'!E63*$P$2 -> 18144.601 | E60: ='raw data'!F63*$P$2 -> 18796.139 | F60: ='raw data'!G63*$P$2 -> 18173.621 | G60: ='raw data'!H63*$P$2 -> 18556.639 | H60: ='raw data'!I63*$Q$2 -> 18312 | I60: ='raw data'!J63*$Q$2 -> 18744.387 | J60: ='raw data'!K63*$R$2 -> 18406.941 | K60: ='raw data'!L63*$R$2 -> 18755.213 | L60: ='raw data'!M63*$R$2 -> 18406.941 | M60: ='raw data'!N63*$R$2 -> 18686.786
A61: 41913 | C61: ='raw data'!D64*$P$2 -> 18976.808 | D61: ='raw data'!E64*$P$2 -> 18237.871 | E61: ='raw data'!F64*$P$2 -> 18870.891 | F61: ='raw data'!G64*$P$2 -> 18277.731 | G61: ='raw data'!H64*$P$2 -> 18631.617 | H61: ='raw data'!I64*$Q$2 -> 18394.22 | I61: ='raw data'!J64*$Q$2 -> 18832.881 | J61: ='raw data'!K64*$R$2 -> 18500.031 | K61: ='raw data'!L64*$R$2 -> 18843.338 | L61: ='raw data'!M64*$R$2 -> 18500.031 | M61: ='raw data'!N64*$R$2 -> 18777.727
A62: 42005 | C62: ='raw data'!D65*$P$2 -> 19061.271 | D62: ='raw data'!E65*$P$2 -> 18267.117 | E62: ='raw data'!F65*$P$2 -> 18949.595 | F62: ='raw data'!G65*$P$2 -> 18370.663 | G62: ='raw data'!H65*$P$2 -> 18707.272 | H62: ='raw data'!I65*$Q$2 -> 18543.823 | I62: ='raw data'!J65*$Q$2 -> 18921.675 | J62: ='raw data'!K65*$R$2 -> 18666.621 | K62: ='raw data'!L65*$R$2 -> 18931.981 | L62: ='raw data'!M65*$R$2 -> 18666.621 | M62: ='raw data'!N65*$R$2 -> 18869.775
A63: 42095 | C63: ='raw data'!D66*$P$2 -> 19149.121 | D63: ='raw data'!E66*$P$2 -> 18443.608 | E63: ='raw data'!F66*$P$2 -> 19030.218 | F63: ='raw data'!G66*$P$2 -> 18489.453 | G63: ='raw data'!H66*$P$2 -> 18782.702 | H63: ='raw data'!I66*$Q$2 -> 18651.377 | I63: ='raw data'!J66*$Q$2 -> 19010.571 | J63: ='raw data'!K66*$R$2 -> 18782.243 | K63: ='raw data'!L66*$R$2 -> 19021.104 | L63: ='raw data'!M66*$R$2 -> 18782.243 | M63: ='raw data'!N66*$R$2 -> 18963.016
A64: 42186 | C64: ='raw data'!D67*$P$2 -> 19240.02 | D64: ='raw data'!E67*$P$2 -> 18512.037 | E64: ='raw data'!F67*$P$2 -> 19113.1 | F64: ='raw data'!G67*$P$2 -> 18580.578 | G64: ='raw data'!H67*$P$2 -> 18858.018 | H64: ='raw data'!I67*$Q$2 -> 18711.691 | I64: ='raw data'!J67*$Q$2 -> 19098.898 | J64: ='raw data'!K67*$R$2 -> 18857.418 | K64: ='raw data'!L67*$R$2 -> 19110.071 | L64: ='raw data'!M67*$R$2 -> 18857.418 | M64: ='raw data'!N67*$R$2 -> 19056.838
A65: 42278 | C65: ='raw data'!D68*$P$2 -> 19333.968 | E65: ='raw data'!F68*$P$2 -> 19198.128 | F65: ='raw data'!G68*$P$2 -> 18621.003 | G65: ='raw data'!H68*$P$2 -> 18932.996 | H65: ='raw data'!I68*$Q$2 -> 18739.053 | I65: ='raw data'!J68*$Q$2 -> 19185.994 | J65: ='raw data'!K68*$R$2 -> 18892.206 | K65: ='raw data'!L68*$R$2 -> 19198.659 | L65: ='raw data'!M68*$R$2 -> 18892.206 | M65: ='raw data'!N68*$R$2 -> 19150.969
A66: 42370 | C66: ='raw data'!D69*$P$2 -> 19431.078 | E66: ='raw data'!F69*$P$2 -> 19284.849 | F66: ='raw data'!G69*$P$2 -> 18659.734 | G66: ='raw data'!H69*$P$2 -> 19006.844 | H66: ='raw data'!I69*$Q$2 -> 18849.46 | I66: ='raw data'!J69*$Q$2 -> 19272.325 | J66: ='raw data'!K69*$R$2 -> 19001.69 | K66: ='raw data'!L69*$R$2 -> 19286.925 | L66: ='raw data'!M69*$R$2 -> 19001.69 | M66: ='raw data'!N69*$R$2 -> 19245.222
A67: 42461 | C67: ='raw data'!D70*$P$2 -> 19531.123 | E67: ='raw data'!F70*$P$2 -> 19374.054 | F67: ='raw data'!G70*$P$2 -> 18725.339 | G67: ='raw data'!H70*$P$2 -> 19079.564 | H67: ='raw data'!I70*$Q$2 -> 18906.459 | I67: ='raw data'!J70*$Q$2 -> 19357.672 | J67: ='raw data'!K70*$R$2 -> 19062.709 | K67: ='raw data'!L70*$R$2 -> 19375.151 | L67: ='raw data'!M70*$R$2 -> 19062.709 | M67: ='raw data'!N70*$R$2 -> 19339.744
A68: 42552 | C68: ='raw data'!D71*$P$2 -> 19633.766 | E68: ='raw data'!F71*$P$2 -> 19465.857 | F68: ='raw data'!G71*$P$2 -> 18859.712 | G68: ='raw data'!H71*$P$2 -> 19152.17 | H68: ='raw data'!I71*$Q$2 -> 19020.108 | I68: ='raw data'!J71*$Q$2 -> 19442.008 | J68: ='raw data'!K71*$R$2 -> 19197.938 | K68: ='raw data'!L71*$R$2 -> 19463.205 | L68: ='raw data'!M71*$R$2 -> 19197.938 | M68: ='raw data'!N71*$R$2 -> 19434.062
A69: 42644 | C69: ='raw data'!D72*$P$2 -> 19738.667 | E69: ='raw data'!F72*$P$2 -> 19560.256 | G69: ='raw data'!H72*$P$2 -> 19225.002 | H69: ='raw data'!I72*$Q$2 -> 19114.617 | I69: ='raw data'!J72*$Q$2 -> 19525.954 | J69: ='raw data'!K72*$R$2 -> 19304.352 | K69: ='raw data'!L72*$R$2 -> 19551.311 | L69: ='raw data'!M72*$R$2 -> 19304.352 | M69: ='raw data'!N72*$R$2 -> 19528.058
A70: 42736 | C70: ='raw data'!D73*$P$2 -> 19845.375 | E70: ='raw data'!F73*$P$2 -> 19658.156 | G70: ='raw data'!H73*$P$2 -> 19298.625 | H70: ='raw data'!I73*$Q$2 -> 19196.746 | I70: ='raw data'!J73*$Q$2 -> 19610.359 | J70: ='raw data'!K73*$R$2 -> 19398.343 | K70: ='raw data'!L73*$R$2 -> 19640.089 | L70: ='raw data'!M73*$R$2 -> 19398.343 | M70: ='raw data'!N73*$R$2 -> 19622.172
A71: 42826 | C71: ='raw data'!D74*$P$2 -> 19954.567 | E71: ='raw data'!F74*$P$2 -> 19759.557 | G71: ='raw data'!H74*$P$2 -> 19373.038 | H71: ='raw data'!I74*$Q$2 -> 19293.458 | I71: ='raw data'!J74*$Q$2 -> 19694.509 | J71: ='raw data'!K74*$R$2 -> 19506.949 | K71: ='raw data'!L74*$R$2 -> 19730.298 | L71: ='raw data'!M74*$R$2 -> 19506.949 | M71: ='raw data'!N74*$R$2 -> 19717.084
A72: 42917 | C72: ='raw data'!D75*$P$2 -> 20065.565 | E72: ='raw data'!F75*$P$2 -> 19863.442 | G72: ='raw data'!H75*$P$2 -> 19448.354 | H72: ='raw data'!I75*$Q$2 -> 19453.109 | I72: ='raw data'!J75*$Q$2 -> 19780.95 | J72: ='raw data'!K75*$R$2 -> 19660.766 | K72: ='raw data'!L75*$R$2 -> 19823.603 | L72: ='raw data'!M75*$R$2 -> 19660.766 | M72: ='raw data'!N75*$R$2 -> 19814.502
A73: 43009 | E73: ='raw data'!F76*$P$2 -> 19969.585 | G73: ='raw data'!H76*$P$2 -> 19525.139 | H73: ='raw data'!I76*$Q$2 -> 19648.741 | I73: ='raw data'!J76*$Q$2 -> 19869.559 | J73: ='raw data'!K76*$R$2 -> 19882.352 | K73: ='raw data'!L76*$R$2 -> 19919.842 | L73: ='raw data'!M76*$R$2 -> 19882.352 | M73: ='raw data'!N76*$R$2 -> 19914.268
A74: 43101 | E74: ='raw data'!F77*$P$2 -> 20077.535 | G74: ='raw data'!H77*$P$2 -> 19604.181 | H74: ='raw data'!I77*$Q$2 -> 19784.839 | I74: ='raw data'!J77*$Q$2 -> 19960.199 | J74: ='raw data'!K77*$R$2 -> 20044.077 | K74: ='raw data'!L77*$R$2 -> 20019.17 | L74: ='raw data'!M77*$R$2 -> 20044.077 | M74: ='raw data'!N77*$R$2 -> 20016.543
A75: 43191 | E75: ='raw data'!F78*$P$2 -> 20187.178 | G75: ='raw data'!H78*$P$2 -> 19684.918 | H75: ='raw data'!I78*$Q$2 -> 19922.807 | I75: ='raw data'!J78*$Q$2 -> 20053.322 | J75: ='raw data'!K78*$R$2 -> 20150.476 | K75: ='raw data'!L78*$R$2 -> 20121.719 | L75: ='raw data'!M78*$R$2 -> 20150.476 | M75: ='raw data'!N78*$R$2 -> 20121.671
A76: 43282 | E76: ='raw data'!F79*$P$2 -> 20298.064 | G76: ='raw data'!H79*$P$2 -> 19767.348 | H76: ='raw data'!I79*$Q$2 -> 20066.657 | I76: ='raw data'!J79*$Q$2 -> 20148.589 | J76: ='raw data'!K79*$R$2 -> 20276.154 | K76: ='raw data'!L79*$R$2 -> 20226.066 | L76: ='raw data'!M79*$R$2 -> 20276.154 | M76: ='raw data'!N79*$R$2 -> 20228.13
A77: 43374 | E77: ='raw data'!F80*$P$2 -> 20410.079 | G77: ='raw data'!H80*$P$2 -> 19851.472 | H77: ='raw data'!I80*$Q$2 -> 20103.134 | I77: ='raw data'!J80*$Q$2 -> 20244.388 | J77: ='raw data'!K80*$R$2 -> 20304.874 | K77: ='raw data'!L80*$R$2 -> 20331.495 | L77: ='raw data'!M80*$R$2 -> 20304.874 | M77: ='raw data'!N80*$R$2 -> 20335.099
A78: 43466 | E78: ='raw data'!F81*$P$2 -> 20522.319 | G78: ='raw data'!H81*$P$2 -> 19937.403 | H78: ='raw data'!I81*$Q$2 -> 20212.236 | I78: ='raw data'!J81*$Q$2 -> 20340.314 | J78: ='raw data'!K81*$R$2 -> 20431.641 | K78: ='raw data'!L81*$R$2 -> 20437.922 | L78: ='raw data'!M81*$R$2 -> 20431.641 | M78: ='raw data'!N81*$R$2 -> 20443.033
A79: 43556 | E79: ='raw data'!F82*$P$2 -> 20635.802 | G79: ='raw data'!H82*$P$2 -> 20025.141 | H79: ='raw data'!I82*$Q$2 -> 20348.266 | I79: ='raw data'!J82*$Q$2 -> 20437.019 | J79: ='raw data'!K82*$R$2 -> 20602.275 | K79: ='raw data'!L82*$R$2 -> 20545.45 | L79: ='raw data'!M82*$R$2 -> 20602.275 | M79: ='raw data'!N82*$R$2 -> 20551.115
A80: 43647 | E80: ='raw data'!F83*$P$2 -> 20749.963 | H80: ='raw data'!I83*$Q$2 -> 20529.359 | I80: ='raw data'!J83*$Q$2 -> 20534.175 | J80: ='raw data'!K83*$R$2 -> 20843.322 | K80: ='raw data'!L83*$R$2 -> 20653.077 | L80: ='raw data'!M83*$R$2 -> 20843.322 | M80: ='raw data'!N83*$R$2 -> 20658.997
A81: 43739 | E81: ='raw data'!F84*$P$2 -> 20864.913 | H81: ='raw data'!I84*$Q$2 -> 20620.314 | I81: ='raw data'!J84*$Q$2 -> 20630.946 | J81: ='raw data'!K84*$R$2 -> 20985.448 | K81: ='raw data'!L84*$R$2 -> 20758.054 | L81: ='raw data'!M84*$R$2 -> 20985.448 | M81: ='raw data'!N84*$R$2 -> 20763.979
A82: 43831 | E82: ='raw data'!F85*$P$2 -> 20980.654 | H82: ='raw data'!I85*$Q$2 -> 20377.993 | I82: ='raw data'!J85*$Q$2 -> 20726.163 | J82: ='raw data'!K85*$R$2 -> 20693.238 | K82: ='raw data'!L85*$R$2 -> 20861.839 | L82: ='raw data'!M85*$R$2 -> 20709.212 | M82: ='raw data'!N85*$R$2 -> 20867.277
A83: 43922 | E83: ='raw data'!F86*$P$2 -> 21096.96 | H83: ='raw data'!I86*$Q$2 -> 18649.056 | I83: ='raw data'!J86*$Q$2 -> 20817.73 | J83: ='raw data'!K86*$R$2 -> 19056.617 | K83: ='raw data'!L86*$R$2 -> 20965.14 | L83: ='raw data'!M86*$R$2 -> 19077.992 | M83: ='raw data'!N86*$R$2 -> 20970.422
A84: 44013 | E84: ='raw data'!F87*$P$2 -> 21213.492 | H84: ='raw data'!I87*$Q$2 -> 20113.843 | I84: ='raw data'!J87*$Q$2 -> 20900.954 | J84: ='raw data'!K87*$R$2 -> 20548.793 | K84: ='raw data'!L87*$R$2 -> 21065.729 | L84: ='raw data'!M87*$R$2 -> 20558.879 | M84: ='raw data'!N87*$R$2 -> 21071.763
A85: 44105 | E85: ='raw data'!F88*$P$2 -> 21330.362 | H85: ='raw data'!I88*$Q$2 -> 20307.582 | I85: ='raw data'!J88*$Q$2 -> 20989.009 | J85: ='raw data'!K88*$R$2 -> 20771.691 | K85: ='raw data'!L88*$R$2 -> 21167.09 | L85: ='raw data'!M88*$R$2 -> 20791.917 | M85: ='raw data'!N88*$R$2 -> 21174.33
...

Sheet data 2012 USD
A1: date | B1: GDP 2014 est | C1: potential GDP 2014 est | D1: GDP 2015 est | E1: potential GDP 2015 est | F1: GDP 2016 est | G1: potential GDP 2016 est | H1: GDP 2022 est | I1: potential GDP 2022 est | J1: deflator from 2009 dollars | K1: deflator from 2012 dollars
A2: 36526 | B2: ='raw data'!C5*$J$2 -> 13005.036 | C2: ='raw data'!D5*$J$2 -> 12692.408 | D2: ='raw data'!E5*$J$2 -> 13005.036 | E2: ='raw data'!F5*$J$2 -> 12757.333 | F2: ='raw data'!G5*$J$2 -> 13005.036 | G2: ='raw data'!H5*$J$2 -> 12770.802 | H2: ='raw data'!I5*$K$2 -> 12935.252 | I2: ='raw data'!J5*$K$2 -> 12756.198 | J2: =deflator_2012_2009 -> 1.052264 | K2: 1
A3: 36617 | B3: ='raw data'!C6*$J$2 -> 13250.634 | C3: ='raw data'!D6*$J$2 -> 12807.315 | D3: ='raw data'!E6*$J$2 -> 13250.634 | E3: ='raw data'!F6*$J$2 -> 12871.609 | F3: ='raw data'!G6*$J$2 -> 13250.634 | G3: ='raw data'!H6*$J$2 -> 12883.71 | H3: ='raw data'!I6*$K$2 -> 13170.749 | I3: ='raw data'!J6*$K$2 -> 12885.55
A4: 36708 | B4: ='raw data'!C7*$J$2 -> 13266.629 | C4: ='raw data'!D7*$J$2 -> 12923.696 | D4: ='raw data'!E7*$J$2 -> 13266.629 | E4: ='raw data'!F7*$J$2 -> 12988.094 | F4: ='raw data'!G7*$J$2 -> 13266.629 | G4: ='raw data'!H7*$J$2 -> 12998.407 | H4: ='raw data'!I7*$K$2 -> 13183.89 | I4: ='raw data'!J7*$K$2 -> 13010.047
A5: 36800 | B5: ='raw data'!C8*$J$2 -> 13341.971 | C5: ='raw data'!D8*$J$2 -> 13041.128 | D5: ='raw data'!E8*$J$2 -> 13341.971 | E5: ='raw data'!F8*$J$2 -> 13106.369 | F5: ='raw data'!G8*$J$2 -> 13341.971 | G5: ='raw data'!H8*$J$2 -> 13114.576 | H5: ='raw data'!I8*$K$2 -> 13262.25 | I5: ='raw data'!J8*$K$2 -> 13129.145
A6: 36892 | B6: ='raw data'!C9*$J$2 -> 13304.089 | C6: ='raw data'!D9*$J$2 -> 13159.508 | D6: ='raw data'!E9*$J$2 -> 13304.089 | E6: ='raw data'!F9*$J$2 -> 13227.274 | F6: ='raw data'!G9*$J$2 -> 13304.089 | G6: ='raw data'!H9*$J$2 -> 13233.482 | H6: ='raw data'!I9*$K$2 -> 13219.251 | I6: ='raw data'!J9*$K$2 -> 13242.626
A7: 36982 | B7: ='raw data'!C10*$J$2 -> 13374.591 | C7: ='raw data'!D10*$J$2 -> 13277.783 | D7: ='raw data'!E10*$J$2 -> 13374.591 | E7: ='raw data'!F10*$J$2 -> 13347.653 | F7: ='raw data'!G10*$J$2 -> 13374.591 | G7: ='raw data'!H10*$J$2 -> 13352.178 | H7: ='raw data'!I10*$K$2 -> 13301.394 | I7: ='raw data'!J10*$K$2 -> 13350.4
A8: 37073 | B8: ='raw data'!C11*$J$2 -> 13332.29 | C8: ='raw data'!D11*$J$2 -> 13395.741 | D8: ='raw data'!E11*$J$2 -> 13332.29 | E8: ='raw data'!F11*$J$2 -> 13467.19 | F8: ='raw data'!G11*$J$2 -> 13332.29 | G8: ='raw data'!H11*$J$2 -> 13470.136 | H8: ='raw data'!I11*$K$2 -> 13248.142 | I8: ='raw data'!J11*$K$2 -> 13452.504
A9: 37165 | B9: ='raw data'!C12*$J$2 -> 13369.33 | C9: ='raw data'!D12*$J$2 -> 13512.858 | D9: ='raw data'!E12*$J$2 -> 13369.33 | E9: ='raw data'!F12*$J$2 -> 13584.938 | F9: ='raw data'!G12*$J$2 -> 13369.33 | G9: ='raw data'!H12*$J$2 -> 13586.306 | H9: ='raw data'!I12*$K$2 -> 13284.881 | I9: ='raw data'!J12*$K$2 -> 13549.578
A10: 37257 | B10: ='raw data'!C13*$J$2 -> 13492.444 | C10: ='raw data'!D13*$J$2 -> 13627.345 | D10: ='raw data'!E13*$J$2 -> 13492.444 | E10: ='raw data'!F13*$J$2 -> 13697.11 | F10: ='raw data'!G13*$J$2 -> 13492.444 | G10: ='raw data'!H13*$J$2 -> 13697.215 | H10: ='raw data'!I13*$K$2 -> 13394.91 | I10: ='raw data'!J13*$K$2 -> 13642.027
A11: 37347 | B11: ='raw data'!C14*$J$2 -> 13566.84 | C11: ='raw data'!D14*$J$2 -> 13742.252 | D11: ='raw data'!E14*$J$2 -> 13566.84 | E11: ='raw data'!F14*$J$2 -> 13807.703 | F11: ='raw data'!G14*$J$2 -> 13566.84 | G11: ='raw data'!H14*$J$2 -> 13806.44 | H11: ='raw data'!I14*$K$2 -> 13477.356 | I11: ='raw data'!J14*$K$2 -> 13731.528
A12: 37438 | B12: ='raw data'!C15*$J$2 -> 13632.922 | C12: ='raw data'!D15*$J$2 -> 13855.37 | D12: ='raw data'!E15*$J$2 -> 13632.922 | E12: ='raw data'!F15*$J$2 -> 13915.56 | F12: ='raw data'!G15*$J$2 -> 13632.922 | G12: ='raw data'!H15*$J$2 -> 13912.824 | H12: ='raw data'!I15*$K$2 -> 13531.741 | I12: ='raw data'!J15*$K$2 -> 13819.422
A13: 37530 | B13: ='raw data'!C16*$J$2 -> 13641.55 | C13: ='raw data'!D16*$J$2 -> 13966.384 | D13: ='raw data'!E16*$J$2 -> 13641.55 | E13: ='raw data'!F16*$J$2 -> 14020.786 | F13: ='raw data'!G16*$J$2 -> 13641.55 | G13: ='raw data'!H16*$J$2 -> 14016.367 | H13: ='raw data'!I16*$K$2 -> 13549.421 | I13: ='raw data'!J16*$K$2 -> 13906.073
A14: 37622 | B14: ='raw data'!C17*$J$2 -> 13712.262 | C14: ='raw data'!D17*$J$2 -> 14074.767 | D14: ='raw data'!E17*$J$2 -> 13712.262 | E14: ='raw data'!F17*$J$2 -> 14123.592 | F14: ='raw data'!G17*$J$2 -> 13712.262 | G14: ='raw data'!H17*$J$2 -> 14117.068 | H14: ='raw data'!I17*$K$2 -> 13619.434 | I14: ='raw data'!J17*$K$2 -> 13992.485
... A60: 41821 | B60: ='raw data'!C63*$J$2 -> 16994.695 | C60: ='raw data'!D63*$J$2 -> 17609.112 | D60: ='raw data'!E63*$J$2 -> 16908.619 | E60: ='raw data'!F63*$J$2 -> 17515.776 | F60: ='raw data'!G63*$J$2 -> 16935.663 | G60: ='raw data'!H63*$J$2 -> 17292.591 | H60: ='raw data'!I63*$K$2 -> 17064.616 | I60: ='raw data'!J63*$K$2 -> 17467.549
A61: 41913 | C61: ='raw data'!D64*$J$2 -> 17684.138 | D61: ='raw data'!E64*$J$2 -> 16995.536 | E61: ='raw data'!F64*$J$2 -> 17585.436 | F61: ='raw data'!G64*$J$2 -> 17032.681 | G61: ='raw data'!H64*$J$2 -> 17362.461 | H61: ='raw data'!I64*$K$2 -> 17141.235 | I61: ='raw data'!J64*$K$2 -> 17550.015
A62: 42005 | C62: ='raw data'!D65*$J$2 -> 17762.847 | D62: ='raw data'!E65*$J$2 -> 17022.79 | E62: ='raw data'!F65*$J$2 -> 17658.778 | F62: ='raw data'!G65*$J$2 -> 17119.283 | G62: ='raw data'!H65*$J$2 -> 17432.963 | H62: ='raw data'!I65*$K$2 -> 17280.647 | I62: ='raw data'!J65*$K$2 -> 17632.761
A63: 42095 | C63: ='raw data'!D66*$J$2 -> 17844.714 | D63: ='raw data'!E66*$J$2 -> 17187.259 | E63: ='raw data'!F66*$J$2 -> 17733.91 | F63: ='raw data'!G66*$J$2 -> 17229.981 | G63: ='raw data'!H66*$J$2 -> 17503.254 | H63: ='raw data'!I66*$K$2 -> 17380.875 | I63: ='raw data'!J66*$K$2 -> 17715.601
A64: 42186 | C64: ='raw data'!D67*$J$2 -> 17929.421 | D64: ='raw data'!E67*$J$2 -> 17251.026 | E64: ='raw data'!F67*$J$2 -> 17811.146 | F64: ='raw data'!G67*$J$2 -> 17314.899 | G64: ='raw data'!H67*$J$2 -> 17573.44 | H64: ='raw data'!I67*$K$2 -> 17437.08 | I64: ='raw data'!J67*$K$2 -> 17797.911
A65: 42278 | C65: ='raw data'!D68*$J$2 -> 18016.969 | E65: ='raw data'!F68*$J$2 -> 17890.382 | F65: ='raw data'!G68*$J$2 -> 17352.57 | G65: ='raw data'!H68*$J$2 -> 17643.31 | H65: ='raw data'!I68*$K$2 -> 17462.579 | I65: ='raw data'!J68*$K$2 -> 17879.075
A66: 42370 | C66: ='raw data'!D69*$J$2 -> 18107.464 | E66: ='raw data'!F69*$J$2 -> 17971.196 | F66: ='raw data'!G69*$J$2 -> 17388.662 | G66: ='raw data'!H69*$J$2 -> 17712.128 | H66: ='raw data'!I69*$K$2 -> 17565.465 | I66: ='raw data'!J69*$K$2 -> 17959.525
A67: 42461 | C67: ='raw data'!D70*$J$2 -> 18200.694 | E67: ='raw data'!F70*$J$2 -> 18054.324 | F67: ='raw data'!G70*$J$2 -> 17449.799 | G67: ='raw data'!H70*$J$2 -> 17779.894 | H67: ='raw data'!I70*$K$2 -> 17618.581 | I67: ='raw data'!J70*$K$2 -> 18039.059
A68: 42552 | C68: ='raw data'!D71*$J$2 -> 18296.345 | E68: ='raw data'!F71*$J$2 -> 18139.874 | F68: ='raw data'!G71*$J$2 -> 17575.018 | G68: ='raw data'!H71*$J$2 -> 17847.555 | H68: ='raw data'!I71*$K$2 -> 17724.489 | I68: ='raw data'!J71*$K$2 -> 18117.649
A69: 42644 | C69: ='raw data'!D72*$J$2 -> 18394.101 | E69: ='raw data'!F72*$J$2 -> 18227.843 | G69: ='raw data'!H72*$J$2 -> 17915.426 | H69: ='raw data'!I72*$K$2 -> 17812.56 | I69: ='raw data'!J72*$K$2 -> 18195.877
A70: 42736 | C70: ='raw data'!D73*$J$2 -> 18493.539 | E70: ='raw data'!F73*$J$2 -> 18319.074 | G70: ='raw data'!H73*$J$2 -> 17984.033 | H70: ='raw data'!I73*$K$2 -> 17889.094 | I70: ='raw data'!J73*$K$2 -> 18274.533
A71: 42826 | C71: ='raw data'!D74*$J$2 -> 18595.293 | E71: ='raw data'!F74*$J$2 -> 18413.567 | G71: ='raw data'!H74*$J$2 -> 18053.377 | H71: ='raw data'!I74*$K$2 -> 17979.218 | I71: ='raw data'!J74*$K$2 -> 18352.951
A72: 42917 | C72: ='raw data'!D75*$J$2 -> 18698.731 | E72: ='raw data'!F75*$J$2 -> 18510.376 | G72: ='raw data'!H75*$J$2 -> 18123.563 | H72: ='raw data'!I75*$K$2 -> 18127.994 | I72: ='raw data'!J75*$K$2 -> 18433.504
A73: 43009 | E73: ='raw data'!F76*$J$2 -> 18609.289 | G73: ='raw data'!H76*$J$2 -> 18195.117 | H73: ='raw data'!I76*$K$2 -> 18310.3 | I73: ='raw data'!J76*$K$2 -> 18516.076
A74: 43101 | E74: ='raw data'!F77*$J$2 -> 18709.885 | G74: ='raw data'!H77*$J$2 -> 18268.776 | H74: ='raw data'!I77*$K$2 -> 18437.127 | I74: ='raw data'!J77*$K$2 -> 18600.543
A75: 43191 | E75: ='raw data'!F78*$J$2 -> 18812.06 | G75: ='raw data'!H78*$J$2 -> 18344.013 | H75: ='raw data'!I78*$K$2 -> 18565.697 | I75: ='raw data'!J78*$K$2 -> 18687.322
A76: 43282 | E76: ='raw data'!F79*$J$2 -> 18915.392 | G76: ='raw data'!H79*$J$2 -> 18420.828 | H76: ='raw data'!I79*$K$2 -> 18699.748 | I76: ='raw data'!J79*$K$2 -> 18776.099
A77: 43374 | E77: ='raw data'!F80*$J$2 -> 19019.777 | G77: ='raw data'!H80*$J$2 -> 18499.222 | H77: ='raw data'!I80*$K$2 -> 18733.741 | I77: ='raw data'!J80*$K$2 -> 18865.373
A78: 43466 | E78: ='raw data'!F81*$J$2 -> 19124.372 | G78: ='raw data'!H81*$J$2 -> 18579.299 | H78: ='raw data'!I81*$K$2 -> 18835.411 | I78: ='raw data'!J81*$K$2 -> 18954.765
A79: 43556 | E79: ='raw data'!F82*$J$2 -> 19230.124 | G79: ='raw data'!H82*$J$2 -> 18661.06 | H79: ='raw data'!I82*$K$2 -> 18962.175 | I79: ='raw data'!J82*$K$2 -> 19044.881
A80: 43647 | E80: ='raw data'!F83*$J$2 -> 19336.508 | H80: ='raw data'!I83*$K$2 -> 19130.932 | I80: ='raw data'!J83*$K$2 -> 19135.419
A81: 43739 | E81: ='raw data'!F84*$J$2 -> 19443.629 | H81: ='raw data'!I84*$K$2 -> 19215.691 | I81: ='raw data'!J84*$K$2 -> 19225.599
A82: 43831 | E82: ='raw data'!F85*$J$2 -> 19551.486 | H82: ='raw data'!I85*$K$2 -> 18989.877 | I82: ='raw data'!J85*$K$2 -> 19314.33
A83: 43922 | E83: ='raw data'!F86*$J$2 -> 19659.869 | H83: ='raw data'!I86*$K$2 -> 17378.712 | I83: ='raw data'!J86*$K$2 -> 19399.659
A84: 44013 | E84: ='raw data'!F87*$J$2 -> 19768.463 | H84: ='raw data'!I87*$K$2 -> 18743.72 | I84: ='raw data'!J87*$K$2 -> 19477.214
A85: 44105 | E85: ='raw data'!F88*$J$2 -> 19877.372 | H85: ='raw data'!I88*$K$2 -> 18924.262 | I85: ='raw data'!J88*$K$2 -> 19559.271
...

Sheet raw data
A1: code | B1: date | C1: GDPC1 | D1: GDPPOT | E1: GDPC1 | F1: GDPPOT | G1: GDPC1 | H1: GDPPOT | I1: GDPC1 | J1: GDPPOT | K1: GDPC1 | L1: GDPPOT | M1: GDPC1 | N1: GDPPOT | Q1: GDPDEF | R1: GDPDEF
A2: variable | C2: real GDP | D2: potential GDP (real) | E2: real GDP | F2: potential GDP (real) | G2: real GDP | H2: potential GDP (real) | I2: real GDP | J2: potential GDP (real) | K2: real GDP | L2: potential GDP (real) | M2: real GDP | N2: potential GDP (real) | Q2: GDP deflator | R2: GDP deflator
A3: downloaded | C3: 2014 | D3: 2014 | E3: 2015 | F3: 2015 | G3: 2016 | H3: 2016 | I3: 2022 | J3: 2022 | K3: 45604 | L3: 45604 | M3: 45969 | N3: 45969 | Q3: 45604 | R3: 45969
A4: units | C4: 2009 USD bn | D4: 2009 USD bn | E4: 2009 USD bn | F4: 2009 USD bn | G4: 2009 USD bn | H4: 2009 USD bn | I4: 2012 USD bn | J4: 2012 USD bn | K4: 2017 USD bn | L4: 2017 USD bn | M4: 2017 USD bn | N4: 2017 USD bn | Q4: 2017=100 | R4: 2017=100 | T4: deflator ratios
B5: 36526 | C5: 12359.1 | D5: 12062 | E5: 12359.1 | F5: 12123.7 | G5: 12359.1 | H5: 12136.5 | I5: 12935.252 | J5: 12756.198 | K5: 13878.147 | L5: 13657.91 | M5: 13878.147 | N5: 13649.992 | Q5: 72.071 | R5: 72.071 | T5: 2012/2009 | U5: =AVERAGE(Q53:Q56)/AVERAGE(Q41:Q44) -> 1.052264
B6: 36617 | C6: 12592.5 | D6: 12171.2 | E6: 12592.5 | F6: 12232.3 | G6: 12592.5 | H6: 12243.8 | I6: 13170.749 | J6: 12885.55 | K6: 14130.908 | L6: 13802.558 | M6: 14130.908 | N6: 13792.736 | Q6: 72.52 | R6: 72.52 | T6: 2017/2009 | U6: =AVERAGE(Q73:Q76)/AVERAGE(Q41:Q44) -> 1.1291821
B7: 36708 | C7: 12607.7 | D7: 12281.8 | E7: 12607.7 | F7: 12343 | G7: 12607.7 | H7: 12352.8 | I7: 13183.89 | J7: 13010.047 | K7: 14145.312 | L7: 13940.66 | M7: 14145.312 | N7: 13929.502 | Q7: 72.944 | R7: 72.944 | T7: 2017/2012 | U7: =AVERAGE(Q73:Q76)/AVERAGE(Q53:Q56) -> 1.0730977
B8: 36800 | C8: 12679.3 | D8: 12393.4 | E8: 12679.3 | F8: 12455.4 | G8: 12679.3 | H8: 12463.2 | I8: 13262.25 | J8: 13129.145 | K8: 14229.765 | L8: 14071.402 | M8: 14229.765 | N8: 14059.357 | Q8: 73.337 | R8: 73.337
B9: 36892 | C9: 12643.3 | D9: 12505.9 | E9: 12643.3 | F9: 12570.3 | G9: 12643.3 | H9: 12576.2 | I9: 13219.251 | J9: 13242.626 | K9: 14183.12 | L9: 14194.982 | M9: 14183.12 | N9: 14182.387 | Q9: 73.822 | R9: 73.822
B10: 36982 | C10: 12710.3 | D10: 12618.3 | E10: 12710.3 | F10: 12684.7 | G10: 12710.3 | H10: 12689 | I10: 13301.394 | J10: 13350.4 | K10: 14271.694 | L10: 14311.54 | M10: 14271.694 | N10: 14298.498 | Q10: 74.266 | R10: 74.266
B11: 37073 | C11: 12670.1 | D11: 12730.4 | E11: 12670.1 | F11: 12798.3 | G11: 12670.1 | H11: 12801.1 | I11: 13248.142 | J11: 13452.504 | K11: 14214.516 | L11: 14421.269 | M11: 14214.516 | N11: 14407.705 | Q11: 74.558 | R11: 74.558
B12: 37165 | C12: 12705.3 | D12: 12841.7 | E12: 12705.3 | F12: 12910.2 | G12: 12705.3 | H12: 12911.5 | I12: 13284.881 | J12: 13549.578 | K12: 14253.574 | L12: 14525.226 | M12: 14253.574 | N12: 14510.935 | Q12: 74.792 | R12: 74.792
B13: 37257 | C13: 12822.3 | D13: 12950.5 | E13: 12822.3 | F13: 13016.8 | G13: 12822.3 | H13: 13016.9 | I13: 13394.91 | J13: 13642.027 | K13: 14372.785 | L13: 14624.003 | M13: 14372.785 | N13: 14608.737 | Q13: 75.027 | R13: 75.027
B14: 37347 | C14: 12893 | D14: 13059.7 | E14: 12893 | F14: 13121.9 | G14: 12893 | H14: 13120.7 | I14: 13477.356 | J14: 13731.528 | K14: 14460.848 | L14: 14719.439 | M14: 14460.848 | N14: 14702.897 | Q14: 75.289 | R14: 75.289
B15: 37438 | C15: 12955.8 | D15: 13167.2 | E15: 12955.8 | F15: 13224.4 | G15: 12955.8 | H15: 13221.8 | I15: 13531.741 | J15: 13819.422 | K15: 14519.633 | L15: 14813.102 | M15: 14519.633 | N15: 14795.138 | Q15: 75.65 | R15: 75.65
B16: 37530 | C16: 12964 | D16: 13272.7 | E16: 12964 | F16: 13324.4 | G16: 12964 | H16: 13320.2 | I16: 13549.421 | J16: 13906.073 | K16: 14537.58 | L16: 14905.536 | M16: 14537.58 | N16: 14886.176 | Q16: 76.089 | R16: 76.089
B17: 37622 | C17: 13031.2 | D17: 13375.7 | E17: 13031.2 | F17: 13422.1 | G17: 13031.2 | H17: 13415.9 | I17: 13619.434 | J17: 13992.485 | K17: 14614.141 | L17: 14997.837 | M17: 14614.141 | N17: 14977.199 | Q17: 76.461 | R17: 76.461
B18: 37712 | C18: 13152.1 | D18: 13474.2 | E18: 13152.1 | F18: 13515.4 | G18: 13152.1 | H18: 13507.1 | I18: 13741.107 | J18: 14079.717 | K18: 14743.567 | L18: 15090.807 | M18: 14743.567 | N18: 15069.026 | Q18: 76.73 | R18: 76.73
B19: 37803 | C19: 13372.4 | D19: 13569.6 | E19: 13372.4 | F19: 13606 | G19: 13372.4 | H19: 13595.1 | I19: 13970.157 | J19: 14166.968 | K19: 14988.782 | L19: 15183.877 | M19: 14988.782 | N19: 15161.013 | Q19: 77.169 | R19: 77.169
... B63: 41821 | C63: 16150.6 | D63: 16734.5 | E63: 16068.8 | F63: 16645.8 | G63: 16094.5 | H63: 16433.7 | I63: 17064.616 | J63: 17467.549 | K63: 18406.941 | L63: 18755.213 | M63: 18406.941 | N63: 18686.786 | Q63: 96.726 | R63: 96.726
B64: 41913 | D64: 16805.8 | E64: 16151.4 | F64: 16712 | G64: 16186.7 | H64: 16500.1 | I64: 17141.235 | J64: 17550.015 | K64: 18500.031 | L64: 18843.338 | M64: 18500.031 | N64: 18777.727 | Q64: 96.822 | R64: 96.822
B65: 42005 | D65: 16880.6 | E65: 16177.3 | F65: 16781.7 | G65: 16269 | H65: 16567.1 | I65: 17280.647 | J65: 17632.761 | K65: 18666.621 | L65: 18931.981 | M65: 18666.621 | N65: 18869.775 | Q65: 96.769 | R65: 96.769
B66: 42095 | D66: 16958.4 | E66: 16333.6 | F66: 16853.1 | G66: 16374.2 | H66: 16633.9 | I66: 17380.875 | J66: 17715.601 | K66: 18782.243 | L66: 19021.104 | M66: 18782.243 | N66: 18963.016 | Q66: 97.325 | R66: 97.325
B67: 42186 | D67: 17038.9 | E67: 16394.2 | F67: 16926.5 | G67: 16454.9 | H67: 16700.6 | I67: 17437.08 | J67: 17797.911 | K67: 18857.418 | L67: 19110.071 | M67: 18857.418 | N67: 19056.838 | Q67: 97.583 | R67: 97.583
B68: 42278 | D68: 17122.1 | F68: 17001.8 | G68: 16490.7 | H68: 16767 | I68: 17462.579 | J68: 17879.075 | K68: 18892.206 | L68: 19198.659 | M68: 18892.206 | N68: 19150.969 | Q68: 97.581 | R68: 97.581
B69: 42370 | D69: 17208.1 | F69: 17078.6 | G69: 16525 | H69: 16832.4 | I69: 17565.465 | J69: 17959.525 | K69: 19001.69 | L69: 19286.925 | M69: 19001.69 | N69: 19245.222 | Q69: 97.496 | R69: 97.496
B70: 42461 | D70: 17296.7 | F70: 17157.6 | G70: 16583.1 | H70: 16896.8 | I70: 17618.581 | J70: 18039.059 | K70: 19062.709 | L70: 19375.151 | M70: 19062.709 | N70: 19339.744 | Q70: 98.159 | R70: 98.159
B71: 42552 | D71: 17387.6 | F71: 17238.9 | G71: 16702.1 | H71: 16961.1 | I71: 17724.489 | J71: 18117.649 | K71: 19197.938 | L71: 19463.205 | M71: 19197.938 | N71: 19434.062 | Q71: 98.41 | R71: 98.41
B72: 42644 | D72: 17480.5 | F72: 17322.5 | H72: 17025.6 | I72: 17812.56 | J72: 18195.877 | K72: 19304.352 | L72: 19551.311 | M72: 19304.352 | N72: 19528.058 | Q72: 98.886 | R72: 98.886
B73: 42736 | D73: 17575 | F73: 17409.2 | H73: 17090.8 | I73: 17889.094 | J73: 18274.533 | K73: 19398.343 | L73: 19640.089 | M73: 19398.343 | N73: 19622.172 | Q73: 99.39 | R73: 99.39
B74: 42826 | D74: 17671.7 | F74: 17499 | H74: 17156.7 | I74: 17979.218 | J74: 18352.951 | K74: 19506.949 | L74: 19730.298 | M74: 19506.949 | N74: 19717.084 | Q74: 99.65 | R74: 99.65
B75: 42917 | D75: 17770 | F75: 17591 | H75: 17223.4 | I75: 18127.994 | J75: 18433.504 | K75: 19660.766 | L75: 19823.603 | M75: 19660.766 | N75: 19814.502 | Q75: 100.162 | R75: 100.162
B76: 43009 | F76: 17685 | H76: 17291.4 | I76: 18310.3 | J76: 18516.076 | K76: 19882.352 | L76: 19919.842 | M76: 19882.352 | N76: 19914.268 | Q76: 100.778 | R76: 100.778
B77: 43101 | F77: 17780.6 | H77: 17361.4 | I77: 18437.127 | J77: 18600.543 | K77: 20044.077 | L77: 20019.17 | M77: 20044.077 | N77: 20016.543 | Q77: 101.419 | R77: 101.419
B78: 43191 | F78: 17877.7 | H78: 17432.9 | I78: 18565.697 | J78: 18687.322 | K78: 20150.476 | L78: 20121.719 | M78: 20150.476 | N78: 20121.671 | Q78: 102.136 | R78: 102.136
B79: 43282 | F79: 17975.9 | H79: 17505.9 | I79: 18699.748 | J79: 18776.099 | K79: 20276.154 | L79: 20226.066 | M79: 20276.154 | N79: 20228.13 | Q79: 102.577 | R79: 102.577
B80: 43374 | F80: 18075.1 | H80: 17580.4 | I80: 18733.741 | J80: 18865.373 | K80: 20304.874 | L80: 20331.495 | M80: 20304.874 | N80: 20335.099 | Q80: 103.019 | R80: 103.019
B81: 43466 | F81: 18174.5 | H81: 17656.5 | I81: 18835.411 | J81: 18954.765 | K81: 20431.641 | L81: 20437.922 | M81: 20431.641 | N81: 20443.033 | Q81: 103.328 | R81: 103.328
B82: 43556 | F82: 18275 | H82: 17734.2 | I82: 18962.175 | J82: 19044.881 | K82: 20602.275 | L82: 20545.45 | M82: 20602.275 | N82: 20551.115 | Q82: 103.862 | R82: 103.862
B83: 43647 | F83: 18376.1 | I83: 19130.932 | J83: 19135.419 | K83: 20843.322 | L83: 20653.077 | M83: 20843.322 | N83: 20658.997 | Q83: 104.192 | R83: 104.192
...

Sheet old raw data 2009-2012 USD
A1: date | B1: GDP 2014 est | C1: potential GDP 2014 est | D1: GDP 2015 est | E1: potential GDP 2015 est | F1: GDP 2016 est | G1: potential GDP 2016 est | H1: GDP 2022 est | I1: potential GDP 2022 est | J1: GDP 2014 est | K1: potential GDP 2014 est | L1: GDP 2015 est | M1: potential GDP 2015 est | N1: GDP 2016 est | O1: potential GDP 2016 est | R1: ratio | S1: ratio | T1: mean ratio
A2: 36526 | B2: 12359.1 | C2: 12062 | D2: 12359.1 | E2: 12123.7 | F2: 12359.1 | G2: 12136.5 | H2: 12935.252 | I2: 12756.198 | J2: =B2*$T$2 -> 12925.229 | K2: =C2*$T$2 -> 12614.52 | L2: =D2*$T$2 -> 12925.229 | M2: =E2*$T$2 -> 12679.047 | N2: =F2*$T$2 -> 12925.229 | O2: =G2*$T$2 -> 12692.433 | R2: =H2/F2 -> 1.0466176 | S2: =I2/G2 -> 1.0510607 | T2: =AVERAGE(R2:R27) -> 1.0458067
A3: 36617 | B3: 12592.5 | C3: 12171.2 | D3: 12592.5 | E3: 12232.3 | F3: 12592.5 | G3: 12243.8 | H3: 13170.749 | I3: 12885.55 | J3: =B3*$T$2 -> 13169.321 | K3: =C3*$T$2 -> 12728.722 | L3: =D3*$T$2 -> 13169.321 | M3: =E3*$T$2 -> 12792.621 | N3: =F3*$T$2 -> 13169.321 | O3: =G3*$T$2 -> 12804.648 | R3: =H3/F3 -> 1.0459201 | S3: =I3/G3 -> 1.0524142
A4: 36708 | B4: 12607.7 | C4: 12281.8 | D4: 12607.7 | E4: 12343 | F4: 12607.7 | G4: 12352.8 | H4: 13183.89 | I4: 13010.047 | J4: =B4*$T$2 -> 13185.217 | K4: =C4*$T$2 -> 12844.389 | L4: =D4*$T$2 -> 13185.217 | M4: =E4*$T$2 -> 12908.392 | N4: =F4*$T$2 -> 13185.217 | O4: =G4*$T$2 -> 12918.641 | R4: =H4/F4 -> 1.0457014 | S4: =I4/G4 -> 1.0532063
A5: 36800 | B5: 12679.3 | C5: 12393.4 | D5: 12679.3 | E5: 12455.4 | F5: 12679.3 | G5: 12463.2 | H5: 13262.25 | I5: 13129.145 | J5: =B5*$T$2 -> 13260.097 | K5: =C5*$T$2 -> 12961.101 | L5: =D5*$T$2 -> 13260.097 | M5: =E5*$T$2 -> 13025.941 | N5: =F5*$T$2 -> 13260.097 | O5: =G5*$T$2 -> 13034.098 | R5: =H5/F5 -> 1.0459765 | S5: =I5/G5 -> 1.0534329
A6: 36892 | B6: 12643.3 | C6: 12505.9 | D6: 12643.3 | E6: 12570.3 | F6: 12643.3 | G6: 12576.2 | H6: 13219.251 | I6: 13242.626 | J6: =B6*$T$2 -> 13222.448 | K6: =C6*$T$2 -> 13078.754 | L6: =D6*$T$2 -> 13222.448 | M6: =E6*$T$2 -> 13146.104 | N6: =F6*$T$2 -> 13222.448 | O6: =G6*$T$2 -> 13152.274 | R6: =H6/F6 -> 1.0455539 | S6: =I6/G6 -> 1.0529911
A7: 36982 | B7: 12710.3 | C7: 12618.3 | D7: 12710.3 | E7: 12684.7 | F7: 12710.3 | G7: 12689 | H7: 13301.394 | I7: 13350.4 | J7: =B7*$T$2 -> 13292.517 | K7: =C7*$T$2 -> 13196.303 | L7: =D7*$T$2 -> 13292.517 | M7: =E7*$T$2 -> 13265.744 | N7: =F7*$T$2 -> 13292.517 | O7: =G7*$T$2 -> 13270.241 | R7: =H7/F7 -> 1.0465051 | S7: =I7/G7 -> 1.0521239
A8: 37073 | B8: 12670.1 | C8: 12730.4 | D8: 12670.1 | E8: 12798.3 | F8: 12670.1 | G8: 12801.1 | H8: 13248.142 | I8: 13452.504 | J8: =B8*$T$2 -> 13250.475 | K8: =C8*$T$2 -> 13313.537 | L8: =D8*$T$2 -> 13250.475 | M8: =E8*$T$2 -> 13384.548 | N8: =F8*$T$2 -> 13250.475 | O8: =G8*$T$2 -> 13387.476 | R8: =H8/F8 -> 1.0456225 | S8: =I8/G8 -> 1.0508866
A9: 37165 | B9: 12705.3 | C9: 12841.7 | D9: 12705.3 | E9: 12910.2 | F9: 12705.3 | G9: 12911.5 | H9: 13284.881 | I9: 13549.578 | J9: =B9*$T$2 -> 13287.288 | K9: =C9*$T$2 -> 13429.936 | L9: =D9*$T$2 -> 13287.288 | M9: =E9*$T$2 -> 13501.574 | N9: =F9*$T$2 -> 13287.288 | O9: =G9*$T$2 -> 13502.933 | R9: =H9/F9 -> 1.0456173 | S9: =I9/G9 -> 1.0494194
A10: 37257 | B10: 12822.3 | C10: 12950.5 | D10: 12822.3 | E10: 13016.8 | F10: 12822.3 | G10: 13016.9 | H10: 13394.91 | I10: 13642.027 | J10: =B10*$T$2 -> 13409.647 | K10: =C10*$T$2 -> 13543.72 | L10: =D10*$T$2 -> 13409.647 | M10: =E10*$T$2 -> 13613.057 | N10: =F10*$T$2 -> 13409.647 | O10: =G10*$T$2 -> 13613.161 | R10: =H10/F10 -> 1.0446574 | S10: =I10/G10 -> 1.0480242
A11: 37347 | B11: 12893 | C11: 13059.7 | D11: 12893 | E11: 13121.9 | F11: 12893 | G11: 13120.7 | H11: 13477.356 | I11: 13731.528 | J11: =B11*$T$2 -> 13483.586 | K11: =C11*$T$2 -> 13657.922 | L11: =D11*$T$2 -> 13483.586 | M11: =E11*$T$2 -> 13722.971 | N11: =F11*$T$2 -> 13483.586 | O11: =G11*$T$2 -> 13721.716 | R11: =H11/F11 -> 1.0453235 | S11: =I11/G11 -> 1.0465545
A12: 37438 | B12: 12955.8 | C12: 13167.2 | D12: 12955.8 | E12: 13224.4 | F12: 12955.8 | G12: 13221.8 | H12: 13531.741 | I12: 13819.422 | J12: =B12*$T$2 -> 13549.262 | K12: =C12*$T$2 -> 13770.346 | L12: =D12*$T$2 -> 13549.262 | M12: =E12*$T$2 -> 13830.166 | N12: =F12*$T$2 -> 13549.262 | O12: =G12*$T$2 -> 13827.447 | R12: =H12/F12 -> 1.0444543 | S12: =I12/G12 -> 1.0451997
A13: 37530 | B13: 12964 | C13: 13272.7 | D13: 12964 | E13: 13324.4 | F13: 12964 | G13: 13320.2 | H13: 13549.421 | I13: 13906.073 | J13: =B13*$T$2 -> 13557.838 | K13: =C13*$T$2 -> 13880.678 | L13: =D13*$T$2 -> 13557.838 | M13: =E13*$T$2 -> 13934.747 | N13: =F13*$T$2 -> 13557.838 | O13: =G13*$T$2 -> 13930.354 | R13: =H13/F13 -> 1.0451574 | S13: =I13/G13 -> 1.0439838
A14: 37622 | B14: 13031.2 | C14: 13375.7 | D14: 13031.2 | E14: 13422.1 | F14: 13031.2 | G14: 13415.9 | H14: 13619.434 | I14: 13992.485 | J14: =B14*$T$2 -> 13628.116 | K14: =C14*$T$2 -> 13988.397 | L14: =D14*$T$2 -> 13628.116 | M14: =E14*$T$2 -> 14036.922 | N14: =F14*$T$2 -> 13628.116 | O14: =G14*$T$2 -> 14030.438 | R14: =H14/F14 -> 1.0451404 | S14: =I14/G14 -> 1.0429777
... A60: 41821 | B60: 16150.6 | C60: 16734.5 | D60: 16068.8 | E60: 16645.8 | F60: 16094.5 | G60: 16433.7 | H60: 17064.616 | I60: 17467.549 | J60: =B60*$T$2 -> 16890.406 | K60: =C60*$T$2 -> 17501.052 | L60: =D60*$T$2 -> 16804.859 | M60: =E60*$T$2 -> 17408.289 | N60: =F60*$T$2 -> 16831.736 | O60: =G60*$T$2 -> 17186.473 | R60: =H60/F60 -> 1.0602762 | S60: =I60/G60 -> 1.0629103
A61: 41913 | C61: 16805.8 | D61: 16151.4 | E61: 16712 | F61: 16186.7 | G61: 16500.1 | H61: 17141.235 | I61: 17550.015 | K61: =C61*$T$2 -> 17575.618 | L61: =D61*$T$2 -> 16891.242 | M61: =E61*$T$2 -> 17477.521 | N61: =F61*$T$2 -> 16928.159 | O61: =G61*$T$2 -> 17255.915 | R61: =H61/F61 -> 1.0589703 | S61: =I61/G61 -> 1.0636308
A62: 42005 | C62: 16880.6 | D62: 16177.3 | E62: 16781.7 | F62: 16269 | G62: 16567.1 | H62: 17280.647 | I62: 17632.761 | K62: =C62*$T$2 -> 17653.844 | L62: =D62*$T$2 -> 16918.329 | M62: =E62*$T$2 -> 17550.414 | N62: =F62*$T$2 -> 17014.229 | O62: =G62*$T$2 -> 17325.984 | R62: =H62/F62 -> 1.0621825 | S62: =I62/G62 -> 1.0643239
A63: 42095 | C63: 16958.4 | D63: 16333.6 | E63: 16853.1 | F63: 16374.2 | G63: 16633.9 | H63: 17380.875 | I63: 17715.601 | K63: =C63*$T$2 -> 17735.208 | L63: =D63*$T$2 -> 17081.788 | M63: =E63*$T$2 -> 17625.085 | N63: =F63*$T$2 -> 17124.248 | O63: =G63*$T$2 -> 17395.844 | R63: =H63/F63 -> 1.0614793 | S63: =I63/G63 -> 1.0650299
A64: 42186 | C64: 17038.9 | D64: 16394.2 | E64: 16926.5 | F64: 16454.9 | G64: 16700.6 | H64: 17437.08 | I64: 17797.911 | K64: =C64*$T$2 -> 17819.396 | L64: =D64*$T$2 -> 17145.164 | M64: =E64*$T$2 -> 17701.847 | N64: =F64*$T$2 -> 17208.644 | O64: =G64*$T$2 -> 17465.599 | R64: =H64/F64 -> 1.0596892 | S64: =I64/G64 -> 1.0657049
A65: 42278 | C65: 17122.1 | E65: 17001.8 | F65: 16490.7 | G65: 16767 | H65: 17462.579 | I65: 17879.075 | K65: =C65*$T$2 -> 17906.407 | M65: =E65*$T$2 -> 17780.596 | N65: =F65*$T$2 -> 17246.084 | O65: =G65*$T$2 -> 17535.041 | R65: =H65/F65 -> 1.058935 | S65: =I65/G65 -> 1.0663252
A66: 42370 | C66: 17208.1 | E66: 17078.6 | F66: 16525 | G66: 16832.4 | H66: 17565.465 | I66: 17959.525 | K66: =C66*$T$2 -> 17996.346 | M66: =E66*$T$2 -> 17860.914 | N66: =F66*$T$2 -> 17281.956 | O66: =G66*$T$2 -> 17603.437 | R66: =H66/F66 -> 1.0629631 | S66: =I66/G66 -> 1.0669616
A67: 42461 | C67: 17296.7 | E67: 17157.6 | F67: 16583.1 | G67: 16896.8 | H67: 17618.581 | I67: 18039.059 | K67: =C67*$T$2 -> 18089.005 | M67: =E67*$T$2 -> 17943.533 | N67: =F67*$T$2 -> 17342.717 | O67: =G67*$T$2 -> 17670.786 | R67: =H67/F67 -> 1.0624419 | S67: =I67/G67 -> 1.0676021
A68: 42552 | C68: 17387.6 | E68: 17238.9 | F68: 16702.1 | G68: 16961.1 | H68: 17724.489 | I68: 18117.649 | K68: =C68*$T$2 -> 18184.068 | M68: =E68*$T$2 -> 18028.557 | N68: =F68*$T$2 -> 17467.168 | O68: =G68*$T$2 -> 17738.032 | R68: =H68/F68 -> 1.0612132 | S68: =I68/G68 -> 1.0681883
A69: 42644 | C69: 17480.5 | E69: 17322.5 | G69: 17025.6 | H69: 17812.56 | I69: 18195.877 | K69: =C69*$T$2 -> 18281.224 | M69: =E69*$T$2 -> 18115.986 | O69: =G69*$T$2 -> 17805.486 | R69: =H69/F69 -> #DIV/0! | S69: =I69/G69 -> 1.0687363
A70: 42736 | C70: 17575 | E70: 17409.2 | G70: 17090.8 | H70: 17889.094 | I70: 18274.533 | K70: =C70*$T$2 -> 18380.053 | M70: =E70*$T$2 -> 18206.658 | O70: =G70*$T$2 -> 17873.673 | R70: =H70/F70 -> #DIV/0! | S70: =I70/G70 -> 1.0692614
A71: 42826 | C71: 17671.7 | E71: 17499 | G71: 17156.7 | H71: 17979.218 | I71: 18352.951 | K71: =C71*$T$2 -> 18481.182 | M71: =E71*$T$2 -> 18300.571 | O71: =G71*$T$2 -> 17942.592 | R71: =H71/F71 -> #DIV/0! | S71: =I71/G71 -> 1.069725
A72: 42917 | C72: 17770 | E72: 17591 | G72: 17223.4 | H72: 18127.994 | I72: 18433.504 | K72: =C72*$T$2 -> 18583.985 | M72: =E72*$T$2 -> 18396.785 | O72: =G72*$T$2 -> 18012.347 | R72: =H72/F72 -> #DIV/0! | S72: =I72/G72 -> 1.0702593
A73: 43009 | E73: 17685 | G73: 17291.4 | H73: 18310.3 | I73: 18516.076 | M73: =E73*$T$2 -> 18495.091 | O73: =G73*$T$2 -> 18083.462 | R73: =H73/F73 -> #DIV/0! | S73: =I73/G73 -> 1.0708257
A74: 43101 | E74: 17780.6 | G74: 17361.4 | H74: 18437.127 | I74: 18600.543 | M74: =E74*$T$2 -> 18595.07 | O74: =G74*$T$2 -> 18156.668 | R74: =H74/F74 -> #DIV/0! | S74: =I74/G74 -> 1.0713734
A75: 43191 | E75: 17877.7 | G75: 17432.9 | H75: 18565.697 | I75: 18687.322 | M75: =E75*$T$2 -> 18696.618 | O75: =G75*$T$2 -> 18231.443 | R75: =H75/F75 -> #DIV/0! | S75: =I75/G75 -> 1.0719572
A76: 43282 | E76: 17975.9 | G76: 17505.9 | H76: 18699.748 | I76: 18776.099 | M76: =E76*$T$2 -> 18799.316 | O76: =G76*$T$2 -> 18307.787 | R76: =H76/F76 -> #DIV/0! | S76: =I76/G76 -> 1.0725583
A77: 43374 | E77: 18075.1 | G77: 17580.4 | H77: 18733.741 | I77: 18865.373 | M77: =E77*$T$2 -> 18903.06 | O77: =G77*$T$2 -> 18385.7 | R77: =H77/F77 -> #DIV/0! | S77: =I77/G77 -> 1.0730912
A78: 43466 | E78: 18174.5 | G78: 17656.5 | H78: 18835.411 | I78: 18954.765 | M78: =E78*$T$2 -> 19007.014 | O78: =G78*$T$2 -> 18465.286 | R78: =H78/F78 -> #DIV/0! | S78: =I78/G78 -> 1.073529
A79: 43556 | E79: 18275 | G79: 17734.2 | H79: 18962.175 | I79: 19044.881 | M79: =E79*$T$2 -> 19112.117 | O79: =G79*$T$2 -> 18546.545
A80: 43647 | E80: 18376.1 | H80: 19130.932 | I80: 19135.419 | M80: =E80*$T$2 -> 19217.848
A81: 43739 | E81: 18477.9 | H81: 19215.691 | I81: 19225.599 | M81: =E81*$T$2 -> 19324.311
A82: 43831 | E82: 18580.4 | H82: 18989.877 | I82: 19314.33 | M82: =E82*$T$2 -> 19431.507
A83: 43922 | E83: 18683.4 | H83: 17378.712 | I83: 19399.659 | M83: =E83*$T$2 -> 19539.225
A84: 44013 | E84: 18786.6 | H84: 18743.72 | I84: 19477.214 | M84: =E84*$T$2 -> 19647.152
A85: 44105 | E85: 18890.1 | H85: 18924.262 | I85: 19559.271 | M85: =E85*$T$2 -> 19755.393
...

Sheet FRED Graph
A1: FRED Graph Observations
A2: Federal Reserve Economic Data
A3: Link: http://research.stlouisfed.org/fred2
A4: Help: http://research.stlouisfed.org/fred2/help-faq
A5: Economic Research Division
A6: Federal Reserve Bank of St. Louis
A8: GDPC1 | B8: Real Gross Domestic Product, Billions of Chained 2009 Dollars, Quarterly, Seasonally Adjusted Annual Rate
A9: GDPPOT | B9: Real Potential Gross Domestic Product, Billions of Chained 2009 Dollars, Quarterly, Not Seasonally Adjusted
A11: Frequency: Quarterly
A12: observation_date | B12: GDPC1 | C12: GDPPOT | D12: output gap
A13: 17168 | B13: 1934.5
A14: 17258 | B14: 1932.3
A15: 17349 | B15: 1930.3
A16: 17441 | B16: 1960.7
A17: 17533 | B17: 1989.5
A18: 17624 | B18: 2021.9
A19: 17715 | B19: 2033.2
A20: 17807 | B20: 2035.3
A21: 17899 | B21: 2007.5 | C21: 2027.9 | D21: =(B21-C21)/C21*100 -> -1.0059668
A22: 17989 | B22: 2000.8 | C22: 2049.5 | D22: =(B22-C22)/C22*100 -> -2.3761893
A23: 18080 | B23: 2022.8 | C23: 2071.4 | D23: =(B23-C23)/C23*100 -> -2.3462393
A24: 18172 | B24: 2004.7 | C24: 2093.8 | D24: =(B24-C24)/C24*100 -> -4.2554208
A25: 18264 | B25: 2084.6 | C25: 2116.8 | D25: =(B25-C25)/C25*100 -> -1.521164
A26: 18354 | B26: 2147.6 | C26: 2140.8 | D26: =(B26-C26)/C26*100 -> 0.31763827
A27: 18445 | B27: 2230.4 | C27: 2165.6 | D27: =(B27-C27)/C27*100 -> 2.9922423
A28: 18537 | B28: 2273.4 | C28: 2191.1 | D28: =(B28-C28)/C28*100 -> 3.7561042
A29: 18629 | B29: 2304.5 | C29: 2217.8 | D29: =(B29-C29)/C29*100 -> 3.9092795
A30: 18719 | B30: 2344.5 | C30: 2245.5 | D30: =(B30-C30)/C30*100 -> 4.4088176
A31: 18810 | B31: 2392.8 | C31: 2273.6 | D31: =(B31-C31)/C31*100 -> 5.2427868
A32: 18902 | B32: 2398.1 | C32: 2301.8 | D32: =(B32-C32)/C32*100 -> 4.1836823
... A283: 41821 | B283: 16150.6 | C283: 16734.5 | D283: =(B283-C283)/C283*100 -> -3.489199
A284: 41913 | C284: 16805.8
A285: 42005 | C285: 16880.6
A286: 42095 | C286: 16958.4
A287: 42186 | C287: 17038.9
A288: 42278 | C288: 17122.1
A289: 42370 | C289: 17208.1
A290: 42461 | C290: 17296.7
A291: 42552 | C291: 17387.6
A292: 42644 | C292: 17480.5
...

Sheet graph
A1: date | B1: output gap
A2: ='FRED Graph'!A21 -> 17899 | B2: ='FRED Graph'!D21 -> -1.0059668
A3: ='FRED Graph'!A22 -> 17989 | B3: ='FRED Graph'!D22 -> -2.3761893
A4: ='FRED Graph'!A23 -> 18080 | B4: ='FRED Graph'!D23 -> -2.3462393
A5: ='FRED Graph'!A24 -> 18172 | B5: ='FRED Graph'!D24 -> -4.2554208
A6: ='FRED Graph'!A25 -> 18264 | B6: ='FRED Graph'!D25 -> -1.521164
A7: ='FRED Graph'!A26 -> 18354 | B7: ='FRED Graph'!D26 -> 0.31763827
A8: ='FRED Graph'!A27 -> 18445 | B8: ='FRED Graph'!D27 -> 2.9922423
A9: ='FRED Graph'!A28 -> 18537 | B9: ='FRED Graph'!D28 -> 3.7561042
A10: ='FRED Graph'!A29 -> 18629 | B10: ='FRED Graph'!D29 -> 3.9092795
A11: ='FRED Graph'!A30 -> 18719 | B11: ='FRED Graph'!D30 -> 4.4088176
A12: ='FRED Graph'!A31 -> 18810 | B12: ='FRED Graph'!D31 -> 5.2427868
A13: ='FRED Graph'!A32 -> 18902 | B13: ='FRED Graph'!D32 -> 4.1836823
... A264: ='FRED Graph'!A283 -> 41821 | B264: ='FRED Graph'!D283 -> -3.489199

Sheet graph 2
B1: data from 2016 | D1: data from 2015 | F1: data from 2014
A2: date | B2: GDP | C2: potential GDP (2016 est.) | D2: GDP | E2: potential GDP (2015 est.) | F2: GDP | G2: potential GDP (2014 est.)
A3: ='FRED Graph'!A225 -> 36526 | B3: 12359.1 | C3: 12136.5 | D3: 12359.1 | E3: 12123.7 | F3: ='FRED Graph'!B225 -> 12359.1 | G3: ='FRED Graph'!C225 -> 12062
A4: ='FRED Graph'!A226 -> 36617 | B4: 12592.5 | C4: 12243.8 | D4: 12592.5 | E4: 12232.3 | F4: ='FRED Graph'!B226 -> 12592.5 | G4: ='FRED Graph'!C226 -> 12171.2
A5: ='FRED Graph'!A227 -> 36708 | B5: 12607.7 | C5: 12352.8 | D5: 12607.7 | E5: 12343 | F5: ='FRED Graph'!B227 -> 12607.7 | G5: ='FRED Graph'!C227 -> 12281.8
A6: ='FRED Graph'!A228 -> 36800 | B6: 12679.3 | C6: 12463.2 | D6: 12679.3 | E6: 12455.4 | F6: ='FRED Graph'!B228 -> 12679.3 | G6: ='FRED Graph'!C228 -> 12393.4
A7: ='FRED Graph'!A229 -> 36892 | B7: 12643.3 | C7: 12576.2 | D7: 12643.3 | E7: 12570.3 | F7: ='FRED Graph'!B229 -> 12643.3 | G7: ='FRED Graph'!C229 -> 12505.9
A8: ='FRED Graph'!A230 -> 36982 | B8: 12710.3 | C8: 12689 | D8: 12710.3 | E8: 12684.7 | F8: ='FRED Graph'!B230 -> 12710.3 | G8: ='FRED Graph'!C230 -> 12618.3
A9: ='FRED Graph'!A231 -> 37073 | B9: 12670.1 | C9: 12801.1 | D9: 12670.1 | E9: 12798.3 | F9: ='FRED Graph'!B231 -> 12670.1 | G9: ='FRED Graph'!C231 -> 12730.4
A10: ='FRED Graph'!A232 -> 37165 | B10: 12705.3 | C10: 12911.5 | D10: 12705.3 | E10: 12910.2 | F10: ='FRED Graph'!B232 -> 12705.3 | G10: ='FRED Graph'!C232 -> 12841.7
A11: ='FRED Graph'!A233 -> 37257 | B11: 12822.3 | C11: 13016.9 | D11: 12822.3 | E11: 13016.8 | F11: ='FRED Graph'!B233 -> 12822.3 | G11: ='FRED Graph'!C233 -> 12950.5
A12: ='FRED Graph'!A234 -> 37347 | B12: 12893 | C12: 13120.7 | D12: 12893 | E12: 13121.9 | F12: ='FRED Graph'!B234 -> 12893 | G12: ='FRED Graph'!C234 -> 13059.7
A13: ='FRED Graph'!A235 -> 37438 | B13: 12955.8 | C13: 13221.8 | D13: 12955.8 | E13: 13224.4 | F13: ='FRED Graph'!B235 -> 12955.8 | G13: ='FRED Graph'!C235 -> 13167.2
A14: ='FRED Graph'!A236 -> 37530 | B14: 12964 | C14: 13320.2 | D14: 12964 | E14: 13324.4 | F14: ='FRED Graph'!B236 -> 12964 | G14: ='FRED Graph'!C236 -> 13272.7
... A61: ='FRED Graph'!A283 -> 41821 | B61: 16094.5 | C61: 16433.7 | D61: 16068.8 | E61: 16645.8 | F61: ='FRED Graph'!B283 -> 16150.6 | G61: ='FRED Graph'!C283 -> 16734.5
A62: ='FRED Graph'!A284 -> 41913 | B62: 16186.7 | C62: 16500.1 | D62: 16151.4 | E62: 16712 | G62: ='FRED Graph'!C284 -> 16805.8
A63: ='FRED Graph'!A285 -> 42005 | B63: 16269 | C63: 16567.1 | D63: 16177.3 | E63: 16781.7 | G63: ='FRED Graph'!C285 -> 16880.6
A64: ='FRED Graph'!A286 -> 42095 | B64: 16374.2 | C64: 16633.9 | D64: 16333.6 | E64: 16853.1 | G64: ='FRED Graph'!C286 -> 16958.4
A65: ='FRED Graph'!A287 -> 42186 | B65: 16454.9 | C65: 16700.6 | D65: 16394.2 | E65: 16926.5 | G65: ='FRED Graph'!C287 -> 17038.9
A66: ='FRED Graph'!A288 -> 42278 | B66: 16490.7 | C66: 16767 | E66: 17001.8 | G66: ='FRED Graph'!C288 -> 17122.1
A67: ='FRED Graph'!A289 -> 42370 | B67: 16525 | C67: 16832.4 | E67: 17078.6 | G67: ='FRED Graph'!C289 -> 17208.1
A68: ='FRED Graph'!A290 -> 42461 | B68: 16583.1 | C68: 16896.8 | E68: 17157.6 | G68: ='FRED Graph'!C290 -> 17296.7
A69: ='FRED Graph'!A291 -> 42552 | B69: 16702.1 | C69: 16961.1 | E69: 17238.9 | G69: ='FRED Graph'!C291 -> 17387.6
A70: ='FRED Graph'!A292 -> 42644 | C70: 17025.6 | E70: 17322.5 | G70: ='FRED Graph'!C292 -> 17480.5
A71: ='FRED Graph'!A293 -> 42736 | C71: 17090.8 | E71: 17409.2 | G71: ='FRED Graph'!C293 -> 17575
A72: ='FRED Graph'!A294 -> 42826 | C72: 17156.7 | E72: 17499 | G72: ='FRED Graph'!C294 -> 17671.7
A73: ='FRED Graph'!A295 -> 42917 | C73: 17223.4 | E73: 17591 | G73: ='FRED Graph'!C295 -> 17770
C74: 17291.4 | E74: 17685
C75: 17361.4 | E75: 17780.6
C76: 17432.9 | E76: 17877.7
C77: 17505.9 | E77: 17975.9
C78: 17580.4 | E78: 18075.1
C79: 17656.5 | E79: 18174.5
C80: 17734.2 | E80: 18275
E81: 18376.1
E82: 18477.9
E83: 18580.4
E84: 18683.4
E85: 18786.6
E86: 18890.1
...
